# 14장

## 자바에서의 예외
- 우리가 예상한, 혹은 예상치 못한 일이 발생하는 것을 미리 예견하고 안전장치를 하는 것

## try와 catch
- try 블록으로 감싸진 곳에서 예외가 발생하면 catch 블록으로 넘어간다.
- catch 블록이 끝나면 다음 코드가 진행된다. (Exception일 경우만, Error라면 멈춘다.)
```java
try{
    // if 예외 발생        
}catch(Exception e){
    // 실행
}
```
## 블록
- try에서 선언한 변수는 catch에서 사용할수 없다.
- 자바에서 변수는 블록 단위로 구분된다.
```java
public class Basic {
    public static void main(String[] args)  {
        Basic sample = new Basic();
        sample.throwMyException(13);
    }
    private void throwMyException(int number) {
        
        if (number > 12){
            try {
                int a = 0;
                System.out.println(a+1);
                throw new MyException("number is over than 12");
            } catch (MyException e) {
                System.out.println(a+2); // 컴파일 에러
            }
        }
    }
}
```

## finally
- try, catch 다음에 finally는 무조건 실행된다.

## 두 개 이상의 catch
- 모든 Exception의 부모는 Exception class 이다.
- catch가 여러개일 때 부모 Exception 먼저 나오면 자식 Exception은 실행될일이 없기 때문에 컴파일 에러가 발생한다.
```java
public class Basic {
    public static void main(String[] args)  {
        Basic sample = new Basic();
        sample.throwMyException(13);
    }
    private void throwMyException(int number) {
        int[] intArray = new int[5];

        try {
            System.out.println(intArray[5]);
        }
        catch (Exception e){
            System.out.println("exception");
        }
        catch (ArrayIndexOutOfBoundsException e) { // 컴파일 에러 발생 
            System.out.println("array exception");
        }
    }
}
```

## 예외라 불리는 것들의 실체
- 모든 예외라 불리는 것들은 모두 Throwable class를 상속 받는다.
- Throwable 직속 자식은 Error, Exception Class가 있다.
- Exception의 직속 자식중 RuntimeExcpetion과 이를 상속받은 클래스는 unchecked exception 이라고 한다.
- 나머지는 checked exception 이라고 한다.
- 예외의 종류는 error, checked exception, uncheckded exception 이 있다.

## throws
- 개발자가 예외를 발생시키는 방법
- try 블록 안에서 throw 라고 명시하고 개발자가 예외 클래스 객체를 생성하면 된다.
```java
public class Basic {
    public static void main(String[] args)  {
        Basic sample = new Basic();
        sample.throwMyException(13);
    }
    private void throwMyException(int number) {
        try {
            if (number > 12){
                throw new MyException("error");
            }
        }catch (MyException e) {
            e.printStackTrace();
        }
    }
}
```
- try, catch문 대신 메소드에 throws를 선언해서 처리할 수 있다.
- checked exception의 경우 메소드를 호출한 곳에서 try-catch 하거나, 메소드를 호출한 메소드에서 throws를 해야한다.
- throws를 연속해서 선언하는것은 좋은 방법이 아니기때문에 try-catch를 사용하는게 좋다.
```java
public class Basic {
    public static void main(String[] args)  {
        Basic sample = new Basic();
        try {
            sample.throwMyException(13);
        } catch (MyException e) {
            e.printStackTrace();
        }
    }
    private void throwMyException(int number) throws MyException {
        if (number > 12){
            throw new MyException("error");
        }
    }
}
```
- unchecked exception의 경우 throws를 따로 선언하지 않아도 된다.
```java
public class Basic {
    public static void main(String[] args)  {
        Basic sample = new Basic();
        sample.throwMyException(13);
    }
    private void throwMyException(int number)  {
        if (number > 12){
            throw new MyRuntimeException("error");
        }
    }
}
```

## 직접해봅시다
```java
public class Calculator {
    public static void main(String[] args) {
        Calculator calculator = new Calculator();
        calculator.printDivide(1,2);
        calculator.printDivide(1,0);
    }

    private void printDivide(double d1, double d2) {
        double result = d1/d2;
        System.out.println(result);
    }
}
```
2. 결과가 Infinity로 나오는 이유
- double 연산결과가 NaN이 나오면 Dboule Class의 toString()에서 "Infinity" 라는 String을 리턴한다.
- NaN은 산술연산에 문제가 있는경우 발생한다.
- 위의 예제의 경우 1을 0으로 나누기 때문에 발생한다.

3. 두번째 값이 0이면 "Second value can't be Zero" 라는 메시지를 갖는 예외를 발생시키자
```java
public class Calculator {
    public static void main(String[] args) {
        Calculator calculator = new Calculator();
        calculator.printDivide(1,2);
        calculator.printDivide(1,0);
    }

    private void printDivide(double d1, double d2) {
        if (d2 == 0){
            throw new NumberCanNotBeZeroException("Second value can't be Zero");
        }
        double result = d1/d2;
        System.out.println(result);
    }
}
```
## 정리해봅시다.

1. 예외를 처리하기 위한 3가지 블록은?
- try, catch, finally

2. 여기서 예외가 발생하니 조심하세요 블록은?
- try

3. 무조건 싫행되야합니다.
- finally

4. 예외의 종류 3가지?
- error, checked Exception, unchekced Exception

5. 프로세스에 치명적인 문제가 발생한 것?
- Error

6. try나 catch 블록 내에서 예외를 발생시키는 키워드는?
- throw

7. 메소드 선언시 어떤 예외를 던질수도 있다고 선언할 때 사용하는 키워드는? 
- throws

8. 직접 예외를 만들떄 어떤 클래스를 상속받아야하나?
- 최대 Exception, 주로 RuntimeException 이 좋다. 
